File: Curie-Weiss Analysis/Squid data/EuAuAs/EuAuAs_Hab_fc_Tscan.dat
[Header]
; MPMS3 Data File (default extension .dat)
; Copyright (c) 2007, Quantum Design, Inc. All rights reserved.
TITLE,
FILEOPENTIME,3932991297.88215,08/16/2024,5:35 pm
BYAPP,MPMS3 w/ AC,1.0,1.1
INFO,MPMS3 Measurement Release 1.1.16 Build 433, MultiVu Release 2.3.4.26,APPNAME
INFO,Linear Motor Servo Controller,MOTOR_MODULE_NAME
INFO,3101-100 N0,MOTOR_HW_VERSION
INFO,MMC1029,MOTOR_SERIAL_NUMBER
INFO,01.04.28,MOTOR_SOFTWARE_VERSION
INFO,Quantum Design Squid Module,SQUID_MODULE_NAME
INFO,3101-501 B0,SQUID_HW_VERSION
INFO,SQM268,SQUID_SERIAL_NUMBER
INFO,01.03.04,SQUID_SOFTWARE_VERSION
INFO,Quantum Design VSM Oven,OVEN_MODULE_NAME
INFO,3101-201 A3,OVEN_HW_VERSION
INFO,OVB317,OVEN_SERIAL_NUMBER
INFO,01.07.07,OVEN_SOFTWARE_VERSION
INFO,SQUID AC,AC_MODULE_NAME
INFO,3101-401 F1,AC_HW_VERSION
INFO,SAC075,AC_SERIAL_NUMBER
INFO,SQUID AC 00.95.07,AC_SOFTWARE_VERSION
INFO,TCI274,COIL_SERIAL_NUMBER
INFO,0,MOMENT_UNITS
INFO,EuAuAs,SAMPLE_MATERIAL
INFO,H//ab,SAMPLE_COMMENT
INFO,62.2,SAMPLE_MASS
INFO,,SAMPLE_VOLUME
INFO,,SAMPLE_MOLECULAR_WEIGHT
INFO,,SAMPLE_SIZE
INFO,,SAMPLE_SHAPE
INFO,Quartz,SAMPLE_HOLDER
INFO,Standard,SAMPLE_HOLDER_DETAIL
INFO,66.26,SAMPLE_OFFSET
DATATYPE,COMMENT,1
DATATYPE,TIME,2
STARTUPAXIS,X,2
STARTUPAXIS,Y1,5
FIELDGROUP, VSM,2,3,4,5,6,8,9,10,11,14,15
FIELDGROUP, DC, 2,3,4,14,56,57,58,59,60,61,62,63,64,65,66,67,68,69
FIELDGROUP, AC, 2,3,4,11,16,17,18,19,20,21,22,23,24,25,26,27,28,29,30
STARTUPGROUP, All
[Data]
Comment,Time Stamp (sec),Temperature (K),Magnetic Field (Oe),Moment (emu),M. Std. Err. (emu),Transport Action,Averaging Time (sec),Frequency (Hz),Peak Amplitude (mm),Center Position (mm),Lockin Signal' (V),Lockin Signal (V),Range,M. Quad. Signal (emu),AC Moment (emu),AC M. Std Err. (emu),AC Phase (deg),AC Phase Std. Err. (deg),AC Susceptibility (emu/Oe),AC Suscept. Std Err. (emu/Oe),AC X' (emu/Oe),AC X' Std Err. (emu/Oe),AC X'' (emu/Oe),AC X'' Std Err. (emu/Oe),AC Drive (Oe),AC Frequency (Hz),AC Averaging Time (sec),AC Cycles,AC Range,AC Measure Type,AC Signal' (V),AC Signal'' (V),AC Trim Coil Ratio,AC Trim Coil Phase,Min. Temperature (K),Max. Temperature (K),Min. Field (Oe),Max. Field (Oe),Mass (grams),Motor Lag (deg),Pressure (Torr),Measure Count,Measurement Number,SQUID Status (code),Motor Status (code),Measure Status (code),Motor Current (amps),Motor Temp. (C),Temp. Status (code),Field Status (code),Chamber Status (code),Chamber Temp (K),Redirection State,Average Temp (K),Rotation Angle (deg),Rotator state,DC Moment Fixed Ctr (emu),DC Moment Err Fixed Ctr (emu),DC Moment Free Ctr (emu),DC Moment Err Free Ctr (emu),DC Fixed Fit,DC Free Fit,DC Calculated Center (mm),DC Calculated Center Err (mm),DC Scan Length (mm),DC Scan Time (s),DC Number of Points,DC Squid Drift,DC Min V (V),DC Max V (V),DC Scans per Measure,Map 01,Map 02,Map 03,Map 04,Map 05,Map 06,Map 07,Map 08,Map 09,Map 10,Map 11,Map 12,Map 13,Map 14,Map 15,Map 16
,3932991341.40716,1.99959886074066,499.813903808594,0.253878618343036,0.000182808780399484,1,2,14.0008964538574,4.99426736293026,32.7900014817715,326.419620756857,49.276480932007,1000,-0.00180446319125241,,,,,,,,,,,,,,,,,,,,,1.99959886074066,1.99959886074066,499.813903808594,499.813903808594,48.8451386095148,5.80858315170597,2.33422589302063,28,1,0,0,1,0.32379150390625,26.3929634094238,1,1,1,1.99959886074066,0,1.99959886074066,,,,,,,,,,,,,,,,,,,,,,,,,,,,,,,,,
,3932991454.96724,2.49943900108337,499.813903808594,0.254005965410666,0.000154184822156656,1,2,14.0008964538574,4.99425856045977,32.7900014817715,326.59583696432,49.2171107322604,1000,-0.00187074807530603,,,,,,,,,,,,,,,,,,,,,2.49943900108337,2.49943900108337,499.813903808594,499.813903808594,48.8427937239571,5.81007669166669,2.60920476913452,28,1,0,0,1,0.324859619140625,27.3704795837402,1,1,1,2.49943900108337,0,2.49943900108337,,,,,,,,,,,,,,,,,,,,,,,,,,,,,,,,,
,3932991564.77742,3.00074696540833,499.813903808594,0.253832535307714,0.000101285753765721,1,2,14.0008964538574,4.99412816433037,32.7900014817715,326.368414566514,49.1344379936059,1000,-0.00190628136085838,,,,,,,,,,,,,,,,,,,,,3.00074696540833,3.00074696540833,499.813903808594,499.813903808594,48.9338534464475,5.8109382631616,2.85013151168823,28,1,0,0,1,0.325546264648438,28.8367557525635,1,1,1,3.00074696540833,0,3.00074696540833,,,,,,,,,,,,,,,,,,,,,,,,,,,,,,,,,
,3932991674.36013,3.4996964931488,499.813903808594,0.254546869620263,0.000137886564267472,1,2,14.0008964538574,4.9940811399986,32.7900014817715,327.280465112002,49.2853767231882,1000,-0.00190127918676725,,,,,,,,,,,,,,,,,,,,,3.4996964931488,3.4996964931488,499.813903808594,499.813903808594,48.9053240054956,5.8107161611764,3.05991363525391,28,1,0,0,1,0.32501220703125,27.8592376708984,1,1,1,3.4996964931488,0,3.4996964931488,,,,,,,,,,,,,,,,,,,,,,,,,,,,,,,,,
,3932991772.56722,3.99994993209839,499.813903808594,0.256437196346761,0.000161141410681395,1,2,14.0008964538574,4.99404796173828,32.7900014817715,329.714088130149,49.6116095614021,1000,-0.00194600984775307,,,,,,,,,,,,,,,,,,,,,3.99943685531616,4.00046300888062,499.813903808594,499.813903808594,48.8736680504667,5.81086625103256,3.23290228843689,28,1,0,0,1,0.32470703125,29.3255138397217,1,1,1,4.00046300888062,0,3.99994993209839,,,,,,,,,,,,,,,,,,,,,,,,,,,,,,,,,
,3932991872.79333,4.49982190132141,499.813903808594,0.260746536735539,0.00014598514958898,1,2,14.0008964538574,4.99407706201817,32.7900014817715,335.262414711333,50.414998458873,1000,-0.00200263949418346,,,,,,,,,,,,,,,,,,,,,4.49979019165039,4.49985361099243,499.813903808594,499.813903808594,48.9217382043994,5.8111209664459,3.38065099716186,28,1,0,0,1,0.32501220703125,28.8367557525635,1,1,1,4.49979019165039,0,4.49982190132141,,,,,,,,,,,,,,,,,,,,,,,,,,,,,,,,,
,3932991971.11005,5.00024557113647,499.813903808594,0.263962348775415,0.000140725178586093,1,2,14.0008964538574,4.99410006624819,32.7900014817715,339.396891561952,51.053099678543,1000,-0.00201487966790291,,,,,,,,,,,,,,,,,,,,,5.00016117095947,5.00032997131348,499.813903808594,499.813903808594,48.8955536490052,5.81052634914535,3.51903581619263,28,1,0,0,1,0.324478149414063,29.3255138397217,1,1,1,5.00016117095947,0,5.00024557113647,,,,,,,,,,,,,,,,,,,,,,,,,,,,,,,,,
,3932992069.07557,5.49993634223938,499.813903808594,0.262179424566873,0.000159878451908181,1,2,14.0008964538574,4.99406166178003,32.7900014817715,337.096539920163,50.7347932801534,1000,-0.00198018731888447,,,,,,,,,,,,,,,,,,,,,5.49924516677856,5.5006275177002,499.813903808594,499.813903808594,48.7736196000052,5.81035741630057,3.64176464080811,28,1,0,0,1,0.324935913085937,28.3479976654053,1,1,1,5.5006275177002,0,5.49993634223938,,,,,,,,,,,,,,,,,,,,,,,,,,,,,,,,,
,3932992166.80529,6.00030636787415,499.813903808594,0.255151940412204,0.00017142591204082,1,2,14.0008964538574,4.99410963524782,32.7900014817715,328.074739428757,49.3163722340861,1000,-0.00197319489117466,,,,,,,,,,,,,,,,,,,,,5.99980449676514,6.00080823898315,499.813903808594,499.813903808594,48.8447477952552,5.8103082833878,3.74885678291321,28,1,0,0,1,0.324249267578125,28.8367557525635,1,1,1,6.00080823898315,0,6.00030636787415,,,,,,,,,,,,,,,,,,,,,,,,,,,,,,,,,
,3932992264.87615,6.49939203262329,499.813903808594,0.243142818436598,0.000113137539916558,1,2,14.0008964538574,4.99412660547765,32.8000001609325,312.635367821369,46.9923457304397,1000,-0.00188273583590904,,,,,,,,,,,,,,,,,,,,,6.4993577003479,6.49942636489868,499.813903808594,499.813903808594,48.8502191948898,5.81043831485167,3.85255980491638,28,1,0,0,1,0.324478149414063,28.3479976654053,1,1,1,6.4993577003479,0,6.49939203262329,,,,,,,,,,,,,,,,,,,,,,,,,,,,,,,,,
,3932992362.86384,6.9999270439148,499.813903808594,0.227948564442151,0.000110638537882212,1,2,14.0008964538574,4.99410491806829,32.7900014817715,293.09469763494,44.0679496107818,1000,-0.00175536916220958,,,,,,,,,,,,,,,,,,,,,6.99973821640015,7.00011587142944,499.813903808594,499.813903808594,48.718905603659,5.81107331979284,3.94988226890564,28,1,0,0,1,0.32470703125,29.3255138397217,1,1,1,7.00011587142944,0,6.9999270439148,,,,,,,,,,,,,,,,,,,,,,,,,,,,,,,,,
,3932992460.88219,7.49985265731812,499.813903808594,0.210406112217113,0.000108692864264076,1,2,14.0008964538574,4.99413964377155,32.7900014817715,270.544874869572,40.6547685749894,1000,-0.00163756423434176,,,,,,,,,,,,,,,,,,,,,7.49978971481323,7.499915599823,499.813903808594,499.813903808594,48.9479227597936,5.81017908337709,4.03278255462646,28,1,0,0,1,0.323944091796875,28.3479976654053,1,1,1,7.49978971481323,0,7.49985265731812,,,,,,,,,,,,,,,,,,,,,,,,,,,,,,,,,
,3932992558.82213,7.99990582466125,499.813903808594,0.193043768495622,0.000106665344288557,1,2,14.0008964538574,4.99409202087846,32.7900014817715,248.219753352004,37.2800735400628,1000,-0.00151757101209632,,,,,,,,,,,,,,,,,,,,,7.99950265884399,8.00030899047852,499.813903808594,499.813903808594,48.8642885082359,5.80999754054926,4.11455011367798,28,1,0,0,1,0.324325561523438,28.8367557525635,1,1,1,7.99950265884399,0,7.99990582466125,,,,,,,,,,,,,,,,,,,,,,,,,,,,,,,,,
,3932992655.03484,8.49977445602417,499.813903808594,0.176702479367249,9.62560965839074E-5,1,2,14.0008964538574,4.99410114206465,32.7900014817715,227.207695262014,34.1285696062923,1000,-0.00138584250698459,,,,,,,,,,,,,,,,,,,,,8.49939155578613,8.50015735626221,499.813903808594,499.813903808594,48.835759067284,5.8098370489827,4.18712282180786,28,1,0,0,1,0.324478149414063,27.8592376708984,1,1,1,8.49939155578613,0,8.49977445602417,,,,,,,,,,,,,,,,,,,,,,,,,,,,,,,,,
,3932992751.07266,9.00020933151245,499.813903808594,0.161933325963962,0.000100393421520517,1,2,14.0008964538574,4.99403367988429,32.7900014817715,208.216267062694,31.2565776620886,1000,-0.00128470181447589,,,,,,,,,,,,,,,,,,,,,9.00018787384033,9.00023078918457,499.813903808594,499.813903808594,48.8635068797167,5.81055299002241,4.26320791244507,28,1,0,0,1,0.324935913085937,28.8367557525635,1,1,1,9.00023078918457,0,9.00020933151245,,,,,,,,,,,,,,,,,,,,,,,,,,,,,,,,,
,3932992848.34052,9.5001745223999,499.813903808594,0.148965869788347,0.00011982949491444,1,2,14.0008964538574,4.99401267642084,32.7900014817715,191.544113397227,28.7362285235234,1000,-0.00119520623287498,,,,,,,,,,,,,,,,,,,,,9.49994087219238,9.50040817260742,499.813903808594,499.813903808594,48.8787486358417,5.8106166918182,4.32333421707153,28,1,0,0,1,0.325775146484375,29.3255138397217,1,1,1,9.50040817260742,0,9.5001745223999,,,,,,,,,,,,,,,,,,,,,,,,,,,,,,,,,
,3932992944.5703,9.99993753433228,499.813903808594,0.137228670343685,8.72172721247045E-5,1,2,14.0008964538574,4.99399870385133,32.7900014817715,176.451720093014,26.4701492574186,1000,-0.00110244695096962,,,,,,,,,,,,,,,,,,,,,9.99984359741211,10.0000314712524,499.813903808594,499.813903808594,48.7591594723994,5.81023020561475,4.39603900909424,28,1,0,0,1,0.324249267578125,28.3479976654053,1,1,1,10.0000314712524,0,9.99993753433228,,,,,,,,,,,,,,,,,,,,,,,,,,,,,,,,,
,3932993031.08077,10.0001134872437,499.813903808594,0.137235259858824,7.77149547200638E-5,1,2,14.0008964538574,4.99396793793193,32.7900014817715,176.458952489642,26.4694299331253,1000,-0.00110387231834256,,,,,,,,,,,,,,,,,,,,,10.0001134872437,10.0001134872437,499.813903808594,499.813903808594,48.8150459115244,5.81005784875759,4.40094327926636,28,1,0,0,1,0.324249267578125,28.8367557525635,1,1,1,10.0001134872437,0,10.0001134872437,,,,,,,,,,,,,,,,,,,,,,,,,,,,,,,,,
,3932993118.71236,11.0001769065857,499.813903808594,0.118039998902766,6.9728628130503E-5,1,2,14.0008964538574,4.9939526606145,32.7900014817715,151.779680194581,22.7486775156296,1000,-0.000963757081435245,,,,,,,,,,,,,,,,,,,,,10.9999580383301,11.0003957748413,499.813903808594,499.813903808594,48.8963352775244,5.81103732525565,4.50980091094971,28,1,0,0,1,0.324630737304687,28.8367557525635,1,1,1,11.0003957748413,0,11.0001769065857,,,,,,,,,,,,,,,,,,,,,,,,,,,,,,,,,
,3932993208.78892,11.9996013641357,499.813903808594,0.102994904668509,6.48374853100023E-5,1,2,14.0008964538574,4.99397583440978,32.7900014817715,132.436076806262,19.8429286862064,1000,-0.000845891637787575,,,,,,,,,,,,,,,,,,,,,11.999587059021,11.9996156692505,499.813903808594,499.813903808594,48.9025883056783,5.81019160405917,4.60959434509277,28,1,0,0,1,0.32501220703125,28.8367557525635,1,1,1,11.9996156692505,0,11.9996013641357,,,,,,,,,,,,,,,,,,,,,,,,,,,,,,,,,
,3932993299.09238,13.0004138946533,499.813903808594,0.0910813670511313,5.04378865473259E-5,1,2,14.0008964538574,4.9939700516586,32.7900014817715,117.118042338099,17.5401478345454,1000,-0.000753885410278403,,,,,,,,,,,,,,,,,,,,,13.0001525878906,13.000675201416,499.813903808594,499.813903808594,48.7998041553994,5.81062040343838,4.69952201843262,28,1,0,0,1,0.32501220703125,31.7693061828613,1,1,1,13.000675201416,0,13.0004138946533,,,,,,,,,,,,,,,,,,,,,,,,,,,,,,,,,
,3932993389.29394,14.0008764266968,499.813903808594,0.0814267827759506,4.39279976164667E-5,1,2,14.0008964538574,4.99400261421992,32.7900014817715,104.705817127203,15.6729487071137,1000,-0.000680276839927187,,,,,,,,,,,,,,,,,,,,,14.0006923675537,14.0010604858398,499.813903808594,499.813903808594,48.9135311049475,5.80996856399028,4.7666130065918,28,1,0,0,1,0.323104858398438,28.8367557525635,1,1,1,14.0006923675537,0,14.0008764266968,,,,,,,,,,,,,,,,,,,,,,,,,,,,,,,,,
,3932993479.52378,15.0001754760742,499.813903808594,0.0735137583243349,4.20978998414858E-5,1,2,14.0008964538574,4.99403360514892,32.7900014817715,94.5316286670115,14.1483119398267,1000,-0.000615466785595296,,,,,,,,,,,,,,,,,,,,,15.0000190734863,15.0003318786621,499.813903808594,499.813903808594,48.9014158628994,5.81049052692296,4.83897304534912,28,1,0,0,1,0.324020385742188,28.3479976654053,1,1,1,15.0003318786621,0,15.0001754760742,,,,,,,,,,,,,,,,,,,,,,,,,,,,,,,,,
,3932993572.59817,16.000524520874,499.813903808594,0.0668824535004428,4.01510645033643E-5,1,2,14.0008964538574,4.99396160718016,32.7900014817715,85.9834366934492,12.9933825814754,100,-0.000465274925531182,,,,,,,,,,,,,,,,,,,,,16.000524520874,16.000524520874,499.813903808594,499.813903808594,48.9162668047648,5.80988445958379,4.8797025680542,28,1,0,0,1,0.323410034179687,29.3255138397217,1,1,1,16.000524520874,0,16.000524520874,,,,,,,,,,,,,,,,,,,,,,,,,,,,,,,,,
,3932993660.49735,17.0000200271606,499.813903808594,0.0612245036661158,3.94181088561399E-5,1,2,14.0008964538574,4.99400804075118,32.7900014817715,78.711929620731,11.8862942670619,100,-0.000432192755760168,,,,,,,,,,,,,,,,,,,,,16.9999332427979,17.0001068115234,499.813903808594,499.813903808594,48.906887262534,5.81020212105768,4.91928005218506,28,1,0,0,1,0.32501220703125,29.3255138397217,1,1,1,16.9999332427979,0,17.0000200271606,,,,,,,,,,,,,,,,,,,,,,,,,,,,,,,,,
,3932993750.6141,18.0001258850098,499.813903808594,0.0565104523334121,3.53874315073434E-5,1,2,14.0008964538574,4.99398311917377,32.7900014817715,72.6513197053225,10.9684106770792,100,-0.000400946529687875,,,,,,,,,,,,,,,,,,,,,18.0001010894775,18.000150680542,499.813903808594,499.813903808594,48.8846108497359,5.81020234595932,4.96870803833008,28,1,0,0,1,0.324935913085937,28.8367557525635,1,1,1,18.000150680542,0,18.0001258850098,,,,,,,,,,,,,,,,,,,,,,,,,,,,,,,,,
,3932993841.09536,19.0001153945923,499.813903808594,0.0524119379805325,3.10997184096263E-5,1,2,14.0008964538574,4.99397413742742,32.7900014817715,67.3822534505132,10.1712355236417,100,-0.00037315005078785,,,,,,,,,,,,,,,,,,,,,19.0001106262207,19.0001201629639,499.813903808594,499.813903808594,48.9147035477263,5.81010835078541,5.00920915603638,28,1,0,0,1,0.324325561523438,29.3255138397217,1,1,1,19.0001106262207,0,19.0001153945923,,,,,,,,,,,,,,,,,,,,,,,,,,,,,,,,,
,3932993931.03835,19.9999780654907,499.813903808594,0.0488747115786563,3.20850431266794E-5,1,2,14.0008964538574,4.99396057701656,32.7900014817715,62.8356636092432,9.47713319112789,100,-0.000353900607835926,,,,,,,,,,,,,,,,,,,,,19.9999446868896,20.0000114440918,499.813903808594,499.813903808594,48.8693690936109,5.81009256233462,5.05190896987915,28,1,0,0,1,0.3253173828125,28.3479976654053,1,1,1,19.9999446868896,0,19.9999780654907,,,,,,,,,,,,,,,,,,,,,,,,,,,,,,,,,