File: Curie-Weiss Analysis/Squid data/EuAuAs/EuAuAs.dat.scans.rw.dat
[Header]
; DC Raw Data File (default extension .raw)
; Copyright 2012, Quantum Design, Inc. All rights reserved.
TITLE,EuAuAs
FILEOPENTIME,3932964027.31326,08/16/2024,10:00 am
BYAPP,MPMS3 DC RAW DATA,1.0,1.1
INFO,MPMS3 Option Release 1.1.16 Build 433, Release 2.3.4.26,APPNAME
INFO,TCI274,COIL_SERIAL_NUMBER
INFO,0,MOMENT_UNITS
INFO,EuAuAs,SAMPLE_MATERIAL
INFO,H//c,SAMPLE_COMMENT
INFO,,SAMPLE_MASS
INFO,,SAMPLE_VOLUME
INFO,,SAMPLE_MOLECULAR_WEIGHT
INFO,,SAMPLE_SIZE
INFO,,SAMPLE_SHAPE
INFO,Quartz,SAMPLE_HOLDER
INFO,Standard,SAMPLE_HOLDER_DETAIL
INFO,66.66,SAMPLE_OFFSET
DATATYPE,COMMENT,1
DATATYPE,TIME,2
STARTUPAXIS,X,3
STARTUPAXIS,Y1,4
STARTUPAXIS,Y2,5
STARTUPAXIS,Y2,6
STARTUPAXIS,Y2,7
STARTUPAXIS,Y3,8
STARTUPAXIS,Y3,9
[Data]
Comment,Time Stamp (sec),Raw Position (mm),Raw Voltage (V),Processed Voltage (V),Fixed C Fitted (V),Free C Fitted (V)
,3932964017.18232,7.13185739517212,0.161507129669189
,3932964017.18232,7.38400030136108,0.176119819283485
,3932964017.18232,7.64742851257324,0.190729603171349
,3932964017.18232,7.92000007629395,0.205357953906059
,3932964017.18232,8.20028591156006,0.220009371638298
,3932964017.18232,8.48742866516113,0.234655544161797
,3932964017.18232,8.77957153320312,0.24928243458271
,3932964017.18232,9.07485675811768,0.26383051276207
,3932964017.18232,9.37385749816895,0.278403699398041
,3932964017.18232,9.67471408843994,0.292937189340591
,3932964017.18232,9.97785663604736,0.307422697544098
,3932964017.18232,10.2819995880127,0.321981489658356
,3932964017.18232,10.586428642273,0.336547613143921
,3932964017.18232,10.8902854919434,0.351055592298508
,3932964017.18232,11.1938571929932,0.365547150373459
,3932964017.18232,11.4965705871582,0.380035251379013
,3932964017.18232,11.7981433868408,0.394483029842377
,3932964017.18232,12.0991430282593,0.408862918615341
,3932964017.18232,12.3975715637207,0.423178374767303
,3932964017.18232,12.6957139968872,0.437520146369934
,3932964017.18232,12.9912853240967,0.451817035675049
,3932964017.18232,13.2868566513062,0.46614021062851
,3932964017.18232,13.5798568725586,0.480497241020203
,3932964017.18232,13.8722848892212,0.494917899370193
,3932964017.18232,14.1630001068115,0.509376108646393
,3932964017.18232,14.453143119812,0.523865401744843
,3932964017.18232,14.7412853240967,0.538419008255005
,3932964017.18232,15.0295715332031,0.552904546260834
,3932964017.18232,15.3171424865723,0.56740814447403
,3932964017.18232,15.6021423339844,0.581826567649841
,3932964017.18232,15.8871421813965,0.59628689289093
,3932964017.18232,16.1715717315674,0.610671162605286
,3932964017.18232,16.4562854766846,0.625086188316345
,3932964017.18232,16.7397136688232,0.63948792219162
,3932964017.18232,17.0227146148682,0.653881013393402
,3932964017.18232,17.3058567047119,0.668275892734528
,3932964017.18232,17.5881423950195,0.682641208171844
,3932964017.18232,17.8712844848633,0.697037816047668
,3932964017.18232,18.1544284820557,0.711414039134979
,3932964017.18232,18.4381427764893,0.725820243358612
,3932964017.18232,18.7210006713867,0.740286290645599
,3932964017.18232,19.0041427612305,0.754776895046234
,3932964017.18232,19.2864284515381,0.769234180450439
,3932964017.18232,19.5690002441406,0.78372186422348
,3932964017.18232,19.8521423339844,0.798087179660797
,3932964017.18232,20.1348571777344,0.812527120113373
,3932964017.18232,20.4184284210205,0.826948344707489
,3932964017.18232,20.7022857666016,0.841308891773224
,3932964017.18232,20.9862861633301,0.855673909187317
,3932964017.18232,21.2695693969727,0.86998063325882
,3932964017.18232,21.5527153015137,0.88433974981308
,3932964017.18232,21.8364276885986,0.898671507835388
,3932964017.18232,22.1198558807373,0.913039445877075
,3932964017.18232,22.4025707244873,0.927357494831085
,3932964017.18232,22.6857147216797,0.94173127412796
,3932964017.18232,22.9691429138184,0.956137001514435
,3932964017.18232,23.2531414031982,0.970445930957794
,3932964017.18232,23.5368576049805,0.984789192676544
,3932964017.18232,23.8211421966553,0.999104619026184
,3932964017.18232,24.1047134399414,1.01342141628265
,3932964017.18232,24.3892841339111,1.02766227722168
,3932964017.18232,24.6738567352295,1.0417857170105
,3932964017.18232,24.9584274291992,1.0559641122818
,3932964017.18232,25.2421436309814,1.07015669345856
,3932964017.18232,25.5262870788574,1.08413422107697
,3932964017.18232,25.8107147216797,1.0981901884079
,3932964017.18232,26.0944290161133,1.1120411157608
,3932964017.18232,26.378999710083,1.12581121921539
,3932964017.18232,26.6631412506104,1.13962864875793
,3932964017.18232,26.9474296569824,1.15323197841644
,3932964017.18232,27.2321434020996,1.16738092899323
,3932964017.18232,27.5164279937744,1.18144559860229
,3932964017.18232,27.8005714416504,1.19489967823029
,3932964017.18232,28.0851440429687,1.20714664459229
,3932964017.18232,28.3692855834961,1.2179046869278
,3932964017.18232,28.6537132263184,1.22687447071075
,3932964017.18232,28.9378566741943,1.23380088806152
,3932964017.18232,29.2218570709229,1.23830199241638
,3932964017.18232,29.5064277648926,1.24029648303986
,3932964017.18232,29.7908573150635,1.24012541770935
,3932964017.18232,30.0751438140869,1.23836421966553
,3932964017.18232,30.360143661499,1.2355968952179
,3932964017.18232,30.6438579559326,1.23224604129791
,3932964017.18232,30.9288578033447,1.22843992710114
,3932964017.18232,31.2124290466309,1.22421157360077
,3932964017.18232,31.4965724945068,1.21938121318817
,3932964017.18232,31.7810001373291,1.21372032165527
,3932964017.18232,32.0651435852051,1.2069696187973
,3932964017.18232,32.3484268188477,1.19893085956573
,3932964017.18232,32.6335716247559,1.18947863578796
,3932964017.18232,32.9175720214844,1.17854738235474
,3932964017.18232,33.201286315918,1.166090965271
,3932964017.18232,33.4864273071289,1.15208435058594
,3932964017.18232,33.7702865600586,1.13678956031799
,3932964017.18232,34.0550003051758,1.12060046195984
,3932964017.18232,34.3384284973145,1.10395431518555
,3932964017.18232,34.6225700378418,1.08720648288727
,3932964017.18232,34.9071426391602,1.0706479549408
,3932964017.18232,35.1915740966797,1.05442357063293
,3932964017.18232,35.4764289855957,1.03864479064941
,3932964017.18232,35.7607154846191,1.02334177494049
,3932964017.18232,36.0452842712402,1.00843739509583
,3932964017.18232,36.3297157287598,0.993863701820374
,3932964017.18232,36.6150016784668,0.979509055614471
,3932964017.18232,36.898998260498,0.965312957763672
,3932964017.18232,37.1831436157227,0.951200187206268
,3932964017.18232,37.4674301147461,0.937126457691193
,3932964017.18232,37.753002166748,0.923060476779938
,3932964017.18232,38.0371437072754,0.908987700939178
,3932964017.18232,38.3228569030762,0.894913911819458
,3932964017.18232,38.6074295043945,0.880816161632538
,3932964017.18232,38.8922843933105,0.866710960865021
,3932964017.18232,39.1769981384277,0.852616786956787
,3932964017.18232,39.4602851867676,0.838532269001007
,3932964017.18232,39.7449989318848,0.824472725391388
,3932964017.18232,40.0288581848145,0.810371339321137
,3932964017.18232,40.3141441345215,0.796351790428162
,3932964017.18232,40.5978546142578,0.782273054122925
,3932964017.18232,40.8824310302734,0.768132627010345
,3932964017.18232,41.1671447753906,0.753967702388763
,3932964017.18232,41.451000213623,0.739738464355469
,3932964017.18232,41.7352867126465,0.72549033164978
,3932964017.18232,42.0197105407715,0.71117240190506
,3932964017.18232,42.3040008544922,0.696737349033356
,3932964017.18232,42.5877151489258,0.682193577289581
,3932964017.18232,42.8722839355469,0.667561054229736
,3932964017.18232,43.1557121276855,0.652847111225128
,3932964017.18232,43.4405708312988,0.63806563615799
,3932964017.18232,43.7248573303223,0.623206675052643
,3932964017.18232,44.008716583252,0.608270108699799
,3932964017.18232,44.2937164306641,0.59325647354126
,3932964017.18232,44.5771446228027,0.578194975852966
,3932964017.18232,44.8618545532227,0.563073396682739
,3932964017.18232,45.1450004577637,0.547858476638794
,3932964017.18232,45.429859161377,0.532571732997894
,3932964017.18232,45.7138557434082,0.517253220081329
,3932964017.18232,45.9987144470215,0.501925468444824
,3932964017.18232,46.2828559875488,0.486616134643555
,3932964017.18232,46.5671424865723,0.471281379461288
,3932964017.18232,46.8508605957031,0.455925524234772
,3932964017.18232,47.1358604431152,0.440549910068512
,3932964017.18232,47.4204292297363,0.425151944160461
,3932964017.18232,47.7045707702637,0.409803122282028
,3932964017.18232,47.989429473877,0.394478350877762
,3932964017.18232,48.2734260559082,0.379192978143692
,3932964017.18232,48.5582847595215,0.363926827907562
,3932964017.18232,48.8428573608398,0.348663032054901
,3932964017.18232,49.1272850036621,0.333433330059052
,3932964017.18232,49.4112854003906,0.318143457174301
,3932964017.18232,49.695858001709,0.30282324552536
,3932964017.18232,49.9804306030273,0.28748881816864
,3932964017.18232,50.2651405334473,0.272158592939377
,3932964017.18232,50.5495719909668,0.256871432065964
,3932964017.18232,50.8332862854004,0.241548597812653
,3932964017.18232,51.1179962158203,0.226195111870766
,3932964017.18232,51.4011421203613,0.210837811231613
,3932964017.18232,51.6851425170898,0.195517808198929
,3932964017.18232,51.9689979553223,0.180275499820709
,3932964017.18232,52.252857208252,0.165073588490486
,3932964017.18232,52.5357131958008,0.149891600012779
,3932964017.18232,52.8198585510254,0.134716302156448
,3932964017.18232,53.1034278869629,0.119563214480877
,3932964017.18232,53.3872833251953,0.104454524815083
,3932964017.18232,53.671573638916,0.0893432796001434
,3932964017.18232,53.9554290771484,0.0742675289511681
,3932964017.18232,54.2389984130859,0.0591885894536972
,3932964017.18232,54.5231437683105,0.0440618507564068
,3932964017.18232,54.8077163696289,0.0290159024298191
,3932964017.18232,55.0914306640625,0.0139402849599719
,3932964017.18232,55.3758583068848,-0.00119876873213798
,3932964017.18232,55.6597137451172,-0.0163130089640617
,3932964017.18232,55.9427146911621,-0.0313582792878151
,3932964017.18232,56.226001739502,-0.0463821738958359
,3932964017.18232,56.5095710754395,-0.0613041333854198
,3932964017.18232,56.7922859191895,-0.0762453824281693
,3932964017.18232,57.0750007629395,-0.0912331268191338
,3932964017.18232,57.3575744628906,-0.106187678873539
,3932964017.18232,57.6399993896484,-0.121102370321751
,3932964017.18232,57.9222869873047,-0.135970667004585
,3932964017.18232,58.2052879333496,-0.150863662362099
,3932964017.18232,58.4878578186035,-0.165767475962639
,3932964017.18232,58.7709999084473,-0.180685922503471
,3932964017.18232,59.0535697937012,-0.195606410503387
,3932964017.18232,59.3361434936523,-0.21051399409771
,3932964017.18232,59.6184272766113,-0.225448176264763
,3932964017.18232,59.9008598327637,-0.240373477339745
,3932964017.18232,60.1829986572266,-0.255293697118759
,3932964017.18232,60.4637145996094,-0.27018666267395
,3932964017.18232,60.7455711364746,-0.285022586584091
,3932964017.18232,61.0277137756348,-0.299856692552567
,3932964017.18232,61.3082847595215,-0.31469988822937
,3932964017.18232,61.5879974365234,-0.329568922519684
,3932964017.18232,61.8671417236328,-0.344446301460266
,3932964017.18232,62.1452865600586,-0.359268307685852
,3932964017.18232,62.4238586425781,-0.37406125664711
,3932964017.18232,62.7001419067383,-0.388868182897568
,3932964017.18232,62.9762840270996,-0.403699994087219
,3932964017.18232,63.2512855529785,-0.418548405170441
,3932964017.18232,63.5248565673828,-0.433373987674713
,3932964017.18232,63.7967147827148,-0.448190659284592
,3932964022.23457,64.4879989624023,0.157193779945374
,3932964022.23457,64.3512878417969,0.172550395131111
,3932964022.23457,64.1818542480469,0.187774866819382
,3932964022.23457,63.9844284057617,0.202904462814331
,3932964022.23457,63.7621421813965,0.21797887980938
,3932964022.23457,63.518856048584,0.23303034901619
,3932964022.23457,63.255859375,0.24809142947197
,3932964022.23457,62.9784278869629,0.263192296028137
,3932964022.23457,62.6860008239746,0.278338104486465
,3932964022.23457,62.3831443786621,0.293539851903915
,3932964022.23457,62.0701408386231,0.308788895606995
,3932964022.23457,61.7507133483887,0.324057221412659
,3932964022.23457,61.4247131347656,0.339334905147553
,3932964022.23457,61.0947113037109,0.354618340730667
,3932964022.23457,60.7611427307129,0.36990150809288
,3932964022.23457,60.4271430969238,0.385225296020508
,3932964022.23457,60.091854095459,0.400513857603073
,3932964022.23457,59.755859375,0.415782958269119
,3932964022.23457,59.4239997863769,0.43106073141098
,3932964022.23457,59.0925750732422,0.4464011490345
,3932964022.23457,58.762996673584,0.461731821298599
,3932964022.23457,58.4367141723633,0.477184623479843
,3932964022.23457,58.1137161254883,0.492729127407074
,3932964022.23457,57.7947120666504,0.508231520652771
,3932964022.23457,57.4782867431641,0.523662686347961
,3932964022.23457,57.1644287109375,0.53901743888855
,3932964022.23457,56.8548583984375,0.554303169250488
,3932964022.23457,56.5488586425781,0.569542169570923
,3932964022.23457,56.2457122802734,0.584798276424408
,3932964022.23457,55.9457130432129,0.600076973438263
,3932964022.23457,55.6478576660156,0.615393161773682
,3932964022.23457,55.3525733947754,0.630727231502533
,3932964022.23457,55.0604286193848,0.646027445793152
,3932964022.23457,54.7687149047852,0.661356747150421
,3932964022.23457,54.4792861938477,0.676719188690186
,3932964022.23457,54.1921424865723,0.692101001739502
,3932964022.23457,53.9060020446777,0.707479536533356
,3932964022.23457,53.6215705871582,0.722837924957275
,3932964022.23457,53.3381462097168,0.738215744495392
,3932964022.23457,53.0547103881836,0.753587663173676
,3932964022.23457,52.7711410522461,0.768945693969727
,3932964022.23457,52.4875717163086,0.784300804138184
,3932964022.23457,52.2044296264648,0.799640655517578
,3932964022.23457,51.9217147827148,0.814985871315002
,3932964022.23457,51.6387176513672,0.830343961715698
,3932964022.23457,51.3581428527832,0.845721900463104
,3932964022.23457,51.0754280090332,0.861093819141388
,3932964022.23457,50.7928581237793,0.876469016075134
,3932964022.23457,50.5101432800293,0.891830086708069
,3932964022.23457,50.2265739440918,0.907187163829804
,3932964022.23457,49.9438591003418,0.922529399394989
,3932964022.23457,49.6612854003906,0.937852561473846
,3932964022.23457,49.3782844543457,0.953194975852966
,3932964022.23457,49.0957145690918,0.968540728092194
,3932964022.23457,48.8129997253418,0.983875036239624
,3932964022.23457,48.5287170410156,0.999237358570099
,3932964022.23457,48.2454299926758,1.01463067531586
,3932964022.23457,47.9614295959473,1.03002762794495
,3932964022.23457,47.6777153015137,1.04541969299316
,3932964022.23457,47.3932876586914,1.06082320213318
,3932964022.23457,47.1098594665527,1.07620453834534
,3932964022.23457,46.8257141113281,1.09153509140015
,3932964022.23457,46.5421447753906,1.10682392120361
,3932964022.23457,46.2574272155762,1.12207293510437
,3932964022.23457,45.9732856750488,1.13728964328766
,3932964022.23457,45.6887168884277,1.15245831012726
,3932964022.23457,45.4045715332031,1.16760265827179
,3932964022.23457,45.120288848877,1.18275141716003
,3932964022.23457,44.8357124328613,1.19780671596527
,3932964022.23457,44.551570892334,1.21277797222137
,3932964022.23457,44.2670021057129,1.22772097587585
,3932964022.23457,43.9822845458984,1.24257063865662
,3932964022.23457,43.6975746154785,1.25740396976471
,3932964022.23457,43.413143157959,1.27221024036407
,3932964022.23457,43.1291389465332,1.28691160678864
,3932964022.23457,42.8447113037109,1.30144989490509
,3932964022.23457,42.5607147216797,1.31591510772705
,3932964022.23457,42.2761421203613,1.33027458190918
,3932964022.23457,41.9917144775391,1.34449553489685
,3932964022.23457,41.7071418762207,1.35855531692505
,3932964022.23457,41.4227142333984,1.37252223491669
,3932964022.23457,41.1389999389648,1.38641023635864
,3932964022.23457,40.8547134399414,1.40026032924652
,3932964022.23457,40.5709991455078,1.4140807390213
,3932964022.23457,40.2868576049805,1.42790293693542
,3932964022.23457,40.002571105957,1.44171023368835
,3932964022.23457,39.7187118530273,1.45571196079254
,3932964022.23457,39.4348564147949,1.47029340267181
,3932964022.23457,39.1508560180664,1.48486745357513
,3932964022.23457,38.8672866821289,1.49871063232422
,3932964022.23457,38.5828552246094,1.51126623153687
,3932964022.23457,38.2982864379883,1.52211797237396
,3932964022.23457,38.013858795166,1.53105866909027
,3932964022.23457,37.7305717468262,1.53780019283295
,3932964022.23457,37.4471435546875,1.54192054271698
,3932964022.23457,37.1641426086426,1.54343736171722
,3932964022.23457,36.880428314209,1.54261827468872
,3932964022.23457,36.5965728759766,1.53968679904938
,3932964022.23457,36.3135719299316,1.53492152690887
,3932964022.23457,36.029712677002,1.52861630916595
,3932964022.23457,35.7464294433594,1.52103078365326
,3932964022.23457,35.4632873535156,1.5123028755188
,3932964022.23457,35.1794281005859,1.50248074531555
,3932964022.23457,34.8957138061523,1.49154996871948
,3932964022.23457,34.6114273071289,1.47949230670929
,3932964022.23457,34.3265724182129,1.4663724899292
,3932964022.23457,34.0429992675781,1.45238125324249
,3932964022.23457,33.7591438293457,1.43773055076599
,3932964022.23457,33.4749984741211,1.42269086837769
,3932964022.23457,33.1902847290039,1.40749680995941
,3932964022.23457,32.9068565368652,1.39233613014221
,3932964022.23457,32.6218566894531,1.37736964225769
,3932964022.23457,32.3378562927246,1.36270034313202
,3932964022.23457,32.0538558959961,1.34831392765045
,3932964022.23457,31.7698554992676,1.33415293693542
,3932964022.23457,31.4857158660889,1.32016634941101
,3932964022.23457,31.201000213623,1.30624341964722
,3932964022.23457,30.9175701141357,1.2923229932785
,3932964022.23457,30.6332855224609,1.27837646007538
,3932964022.23457,30.3488578796387,1.26434981822968
,3932964022.23457,30.0642852783203,1.2502555847168
,3932964022.23457,29.7805709838867,1.2360645532608
,3932964022.23457,29.4964275360107,1.22173953056335
,3932964022.23457,29.2119998931885,1.20735561847687
,3932964022.23457,28.9284286499023,1.1929327249527
,3932964022.23457,28.6442852020264,1.17841064929962
,3932964022.23457,28.360143661499,1.16377878189087
,3932964022.23457,28.0761432647705,1.14910912513733
,3932964022.23457,27.7915725708008,1.13433635234833
,3932964022.23457,27.5074291229248,1.11952912807465
,3932964022.23457,27.2231426239014,1.10472667217255
,3932964022.23457,26.9392852783203,1.08987259864807
,3932964022.23457,26.6548557281494,1.07496774196625
,3932964022.23457,26.3714275360107,1.05999517440796
,3932964022.23457,26.0872859954834,1.0449366569519
,3932964022.23457,25.8030014038086,1.0298056602478
,3932964022.23457,25.5185718536377,1.0146176815033
,3932964022.23457,25.2350006103516,0.999347686767578
,3932964022.23457,24.9507160186768,0.984025478363037
,3932964022.23457,24.6669998168945,0.968685150146484
,3932964022.23457,24.3819999694824,0.953329563140869
,3932964022.23457,24.0978565216064,0.937982082366943
,3932964022.23457,23.8129997253418,0.922625958919525
,3932964022.23457,23.5287132263184,0.907266318798065
,3932964022.23457,23.2445697784424,0.891878545284271
,3932964022.23457,22.9610004425049,0.876492023468018
,3932964022.23457,22.6768569946289,0.861097514629364
,3932964022.23457,22.3925704956055,0.845669388771057
,3932964022.23457,22.1089992523193,0.830217659473419
,3932964022.23457,21.8237133026123,0.814754247665405
,3932964022.23457,21.5395698547363,0.799299478530884
,3932964022.23457,21.2557144165039,0.783834457397461
,3932964022.23457,20.9707145690918,0.768373131752014
,3932964022.23457,20.6865730285645,0.752955079078674
,3932964022.23457,20.4020004272461,0.737579643726349
,3932964022.23457,20.1187152862549,0.722248375415802
,3932964022.23457,19.8337154388428,0.706941962242126
,3932964022.23457,19.550142288208,0.691647708415985
,3932964022.23457,19.2658576965332,0.676346302032471
,3932964022.23457,18.9815711975098,0.66103607416153
,3932964022.23457,18.6972846984863,0.645750641822815
,3932964022.23457,18.413143157959,0.630476295948029
,3932964022.23457,18.1288566589355,0.615215241909027
,3932964022.23457,17.844856262207,0.599964797496796
,3932964022.23457,17.5602855682373,0.584722995758057
,3932964022.23457,17.2765712738037,0.569493353366852
,3932964022.23457,16.9919986724854,0.554237365722656
,3932964022.23457,16.7075729370117,0.538875162601471
,3932964022.23457,16.4235725402832,0.522954821586609
,3932964022.23457,16.1392860412598,0.506830632686615
,3932964022.23457,15.8549995422363,0.491317808628082
,3932964022.23457,15.5702857971191,0.477106213569641
,3932964022.23457,15.2859992980957,0.464676886796951
,3932964022.23457,15.0015707015991,0.454214155673981
,3932964022.23457,14.7177152633667,0.445842057466507
,3932964022.23457,14.4334287643433,0.439699500799179
,3932964022.23457,14.1491432189941,0.436016589403152
,3932964022.23457,13.864143371582,0.434672981500626
,3932964022.23457,13.5805711746216,0.435386508703232
,3932964022.23457,13.2967138290405,0.4379623234272
,3932964022.23457,13.011999130249,0.442201524972916
,3932964022.23457,12.7280006408691,0.447892993688583
,3932964022.23457,12.4440002441406,0.454937994480133
,3932964022.23457,12.160285949707,0.463282495737076
,3932964022.23457,11.8755712509155,0.472971498966217
,3932964022.23457,11.590856552124,0.483973979949951
,3932964022.23457,11.3072853088379,0.496303230524063
,3932964022.23457,11.0231437683105,0.509909868240356
,3932964022.23457,10.7390003204346,0.524587333202362
,3932964022.23457,10.454571723938,0.540063440799713
,3932964022.23457,10.1701431274414,0.556000530719757
,3932964022.23457,9.88614273071289,0.572092294692993
,3932964022.23457,9.60171413421631,0.588141679763794
,3932964022.23457,9.31742858886719,0.604025721549988
,3932964022.23457,9.03314304351807,0.619680106639862
,3932964022.23457,8.74842834472656,0.635117471218109
,3932964022.23457,8.4642858505249,0.650371313095093
,3932964022.23457,8.18000030517578,0.665486216545105
,3932964022.23457,7.89557123184204,0.680491507053375
,3932964022.23457,7.61114263534546,0.695441663265228
,3932964079.54831,7.15428590774536,-0.00669726403430104
,3932964079.54831,7.41128587722778,-0.00659067323431373
,3932964079.54831,7.6775712966919,-0.00648003024980426
,3932964079.54831,7.95228576660156,-0.00635550729930401
,3932964079.54831,8.23428630828857,-0.00621933629736304
,3932964079.54831,8.52071380615234,-0.00607396895065904
,3932964079.54831,8.81271457672119,-0.00591787323355675
,3932964079.54831,9.10771465301514,-0.00575011176988482
,3932964079.54831,9.40657138824463,-0.0055731707252562
,3932964079.54831,9.70657157897949,-0.00537765072658658
,3932964079.54831,10.008713722229,-0.00517480773851275
,3932964079.54831,10.3102855682373,-0.0049534528516233
,3932964079.54831,10.613429069519,-0.00471978588029742
,3932964079.54831,10.9151430130005,-0.0044681690633297
,3932964079.54831,11.2177152633667,-0.00420343922451138
,3932964079.54831,11.5182857513428,-0.00392106641083956
,3932964079.54831,11.8182859420776,-0.00362145947292447
,3932964079.54831,12.118143081665,-0.00330451573245227
,3932964079.54831,12.4154281616211,-0.00296548451296985
,3932964079.54831,12.711428642273,-0.00260906573385
,3932964079.54831,13.0071420669556,-0.00222797063179314
,3932964079.54831,13.3004283905029,-0.00182364694774151
,3932964079.54831,13.5937147140503,-0.00139118952210993
,3932964079.54831,13.8844289779663,-0.000942179234698415
,3932964079.54831,14.1745719909668,-0.000454528053523973
,3932964079.54831,14.4640007019043,5.67265997233335E-5
,3932964079.54831,14.7515707015991,0.000600985193159431
,3932964079.54831,15.0387144088745,0.0011742286151275
,3932964079.54831,15.3255710601807,0.00178921245969832
,3932964079.54831,15.6102857589722,0.00243677431717515
,3932964079.54831,15.8950004577637,0.00311892386525869
,3932964079.54831,16.1795711517334,0.00384569214656949
,3932964079.54831,16.4625720977783,0.00462005846202374
,3932964079.54831,16.7465705871582,0.00544423749670386
,3932964079.54831,17.029857635498,0.00631521455943584
,3932964079.54831,17.3127155303955,0.00724297016859055
,3932964079.54831,17.5965709686279,0.00822661723941565
,3932964079.54831,17.8799991607666,0.00926525332033634
,3932964079.54831,18.1634292602539,0.0103662703186274
,3932964079.54831,18.4474277496338,0.0115320859476924
,3932964079.54831,18.7301425933838,0.0127577958628535
,3932964079.54831,19.0128574371338,0.0140538914129138
,3932964079.54831,19.296142578125,0.015415039844811
,3932964079.54831,19.5791435241699,0.0168497059494257
,3932964079.54831,19.8621425628662,0.0183477252721786
,3932964079.54831,20.1454277038574,0.0199187844991684
,3932964079.54831,20.4290008544922,0.0215622708201408
,3932964079.54831,20.7125701904297,0.023267850279808
,3932964079.54831,20.9967136383057,0.0250317547470331
,3932964079.54831,21.280143737793,0.0268506351858377
,3932964079.54831,21.5632858276367,0.028706468641758
,3932964079.54831,21.8472843170166,0.0306067671626806
,3932964079.54831,22.1307144165039,0.0325213707983494
,3932964079.54831,22.4139995574951,0.0344405882060528
,3932964079.54831,22.6968574523926,0.036343339830637
,3932964079.54831,22.9807147979736,0.0382048264145851
,3932964079.54831,23.263427734375,0.0400034561753273
,3932964079.54831,23.5478572845459,0.0417093597352505
,3932964079.54831,23.8311424255371,0.0432820692658424
,3932964079.54831,24.1147136688232,0.0446825064718723
,3932964079.54831,24.399284362793,0.0458724349737167
,3932964079.54831,24.6834278106689,0.0468026101589203
,3932964079.54831,24.9674301147461,0.0474193282425404
,3932964079.54831,25.2519989013672,0.0476792044937611
,3932964079.54831,25.5360012054443,0.0475297868251801
,3932964079.54831,25.8210010528564,0.0469275750219822
,3932964079.54831,26.1048564910889,0.045817106962204
,3932964079.54831,26.3889999389648,0.0441623963415623
,3932964079.54831,26.6727142333984,0.0419276654720306
,3932964079.54831,26.9577140808105,0.0390896648168564
,3932964079.54831,27.2422847747803,0.0356058776378632
,3932964079.54831,27.5265731811523,0.0314862430095673
,3932964079.54831,27.8107147216797,0.0267253443598747
,3932964079.54831,28.0951442718506,0.0213228818029165
,3932964079.54831,28.3795700073242,0.0153004284948111
,3932964079.54831,28.6638565063477,0.00868940446525812
,3932964079.54831,28.9482860565186,0.00151761947199702
,3932964079.54831,29.2321434020996,-0.00615736469626427
,3932964079.54831,29.5170001983643,-0.0143155390396714
,3932964079.54831,29.8012866973877,-0.0228609200567007
,3932964079.54831,30.0857162475586,-0.0317647308111191
,3932964079.54831,30.3697147369385,-0.0409289635717869
,3932964079.54831,30.6535720825195,-0.0502881370484829
,3932964079.54831,30.9385719299316,-0.0598097927868366
,3932964079.54831,31.2225704193115,-0.0693470239639282
,3932964079.54831,31.5067138671875,-0.0788570418953896
,3932964079.54831,31.7901439666748,-0.0882216244935989
,3932964079.54831,32.0742835998535,-0.0974005535244942
,3932964079.54831,32.358715057373,-0.106270104646683
,3932964079.54831,32.6425704956055,-0.114721432328224
,3932964079.54831,32.9272842407227,-0.122674353420734
,3932964079.54831,33.2111434936523,-0.13003696501255
,3932964079.54831,33.4952850341797,-0.136703252792358
,3932964079.54831,33.7795715332031,-0.142576187849045
,3932964079.54831,34.0644302368164,-0.147597938776016
,3932964079.54831,34.3482856750488,-0.15164940059185
,3932964079.54831,34.6327133178711,-0.154701262712479
,3932964079.54831,34.9168586730957,-0.156689718365669
,3932964079.54831,35.2014274597168,-0.157597661018372
,3932964079.54831,35.4862861633301,-0.157396242022514
,3932964079.54831,35.7698554992676,-0.15608923137188
,3932964079.54831,36.0545692443848,-0.153698652982712
,3932964079.54831,36.339714050293,-0.15025520324707
,3932964079.54831,36.6248550415039,-0.145815521478653
,3932964079.54831,36.9091415405273,-0.140455737709999
,3932964079.54831,37.1940002441406,-0.134246155619621
,3932964079.54831,37.4782867431641,-0.127288967370987
,3932964079.54831,37.7624282836914,-0.119662962853909
,3932964079.54831,38.0474281311035,-0.111458383500576
,3932964079.54831,38.3322868347168,-0.102787055075169
,3932964079.54831,38.6171417236328,-0.093753844499588
,3932964079.54831,38.9021453857422,-0.0844299867749214
,3932964079.54831,39.1864280700684,-0.0749770477414131
,3932964079.54831,39.4705696105957,-0.0654430091381073
,3932964079.54831,39.755428314209,-0.055892713367939
,3932964079.54831,40.0398559570313,-0.0464283414185047
,3932964079.54831,40.3244285583496,-0.03714469820261
,3932964079.54831,40.6082878112793,-0.0281178653240204
,3932964079.54831,40.8925704956055,-0.0193952508270741
,3932964079.54831,41.1761436462402,-0.0110796531662345
,3932964079.54831,41.4614295959473,-0.00315107638016343
,3932964079.54831,41.745288848877,0.0042606764473021
,3932964079.54831,42.0299987792969,0.0111476527526975
,3932964079.54831,42.3142852783203,0.0174455661326647
,3932964079.54831,42.5975723266602,0.0231334492564201
,3932964079.54831,42.8815727233887,0.028183089569211
,3932964079.54831,43.1660003662109,0.0326066911220551
,3932964079.54831,43.4501419067383,0.0363889634609222
,3932964079.54831,43.7350006103516,0.0395369715988636
,3932964079.54831,44.019287109375,0.042052373290062
,3932964079.54831,44.3032875061035,0.0439764633774757
,3932964079.54831,44.5874252319336,0.0453451238572598
,3932964079.54831,44.8711433410645,0.0461796037852764
,3932964079.54831,45.1552886962891,0.0465388000011444
,3932964079.54831,45.4401397705078,0.0464718192815781
,3932964079.54831,45.7241401672363,0.0460238642990589
,3932964079.54831,46.0082855224609,0.0452421084046364
,3932964079.54831,46.2924270629883,0.044185284525156
,3932964079.54831,46.5770034790039,0.0428864806890488
,3932964079.54831,46.861572265625,0.041406225413084
,3932964079.54831,47.1467132568359,0.0397660247981548
,3932964079.54831,47.4308586120605,0.0380229987204075
,3932964079.54831,47.7148590087891,0.0361989252269268
,3932964079.54831,47.9997100830078,0.0343298763036728
,3932964079.54831,48.2832870483398,0.032437976449728
,3932964079.54831,48.568286895752,0.0305437054485083
,3932964079.54831,48.8524284362793,0.0286609642207623
,3932964079.54831,49.1370010375977,0.026814566925168
,3932964079.54831,49.4217147827148,0.0250030439347029
,3932964079.54831,49.7051429748535,0.023255230858922
,3932964079.54831,49.9901428222656,0.0215515419840813
,3932964079.54831,50.2742881774902,0.0199142880737782
,3932964079.54831,50.5581436157227,0.0183456987142563
,3932964079.54831,50.8417129516602,0.0168479699641466
,3932964079.54831,51.1257133483887,0.015417049638927
,3932964079.54831,51.4094276428223,0.0140539258718491
,3932964079.54831,51.6940002441406,0.0127570973709226
,3932964079.54831,51.9784278869629,0.0115265175700188
,3932964079.54831,52.2624282836914,0.0103665767237544
,3932964079.54831,52.5471420288086,0.00926217064261436
,3932964079.54831,52.8305702209473,0.00822714436799288
,3932964079.54831,53.1152877807617,0.0072396663017571
,3932964079.54831,53.3981437683105,0.0063265054486692
,3932964079.54831,53.6818542480469,0.00544946594163775
,3932964079.54831,53.9657135009766,0.00463247345760465
,3932964079.54831,54.2494277954102,0.00385723845101893
,3932964079.54831,54.5335693359375,0.00313614122569561
,3932964079.54831,54.8174285888672,0.00245005753822625
,3932964079.54831,55.1018562316895,0.00180929072666913
,3932964079.54831,55.3858604431152,0.00120529113337398
,3932964079.54831,55.6692886352539,0.000638025172520429
,3932964079.54831,55.9524269104004,0.000102571088063996
,3932964079.54831,56.2360000610352,-0.00039276058669202
,3932964079.54831,56.518856048584,-0.000864880508743226
,3932964079.54831,56.8018569946289,-0.00130730029195547
,3932964079.54831,57.0844268798828,-0.0017204798059538
,3932964079.54831,57.3664321899414,-0.00210951082408428
,3932964079.54831,57.6494293212891,-0.0024761816021055
,3932964079.54831,57.9327163696289,-0.00282243336550891
,3932964079.54831,58.2157135009766,-0.00314251030795276
,3932964079.54831,58.4978561401367,-0.00345151801593602
,3932964079.54831,58.7804298400879,-0.00373286893591285
,3932964079.54831,59.0629997253418,-0.00400805519893765
,3932964079.54831,59.3460006713867,-0.0042586331255734
,3932964079.54831,59.6279983520508,-0.004499776288867
,3932964079.54831,59.9102897644043,-0.00472206762060523
,3932964079.54831,60.1927146911621,-0.00493626995012164
,3932964079.54831,60.4742889404297,-0.00513286283239722
,3932964079.54831,60.7557144165039,-0.00532358093187213
,3932964079.54831,61.0370025634766,-0.00549994222819805
,3932964079.54831,61.3170013427734,-0.00566809577867389
,3932964079.54831,61.5971450805664,-0.00582124525681138
,3932964079.54831,61.8762855529785,-0.00597073370590806
,3932964079.54831,62.1552886962891,-0.00611128145828843
,3932964079.54831,62.4328575134277,-0.006242701318115
,3932964079.54831,62.7101402282715,-0.00636645779013634
,3932964079.54831,62.9862823486328,-0.00648404890671372
,3932964079.54831,63.2614288330078,-0.00659036682918668
,3932964079.54831,63.5347137451172,-0.00669666798785329
,3932964079.54831,63.8065719604492,-0.00679595209658146
,3932964084.32985,64.4174270629883,-0.00697386357933283
,3932964084.32985,64.2545700073242,-0.00692096864804626
,3932964084.32985,64.0648574829102,-0.00686177285388112
,3932964084.32985,63.8541412353516,-0.00678581930696964
,3932964084.32985,63.6225738525391,-0.00670337770134211
,3932964084.32985,63.3751411437988,-0.00661155208945274
,3932964084.32985,63.1124267578125,-0.00651034340262413
,3932964084.32985,62.8357124328613,-0.00639554485678673
,3932964084.32985,62.5489997863769,-0.00627086870372295
,3932964084.32985,62.2521438598633,-0.00613386323675513
,3932964084.32985,61.9461441040039,-0.00598137779161334
,3932964084.32985,61.6352882385254,-0.00581836747005582
,3932964084.32985,61.3184280395508,-0.00563892349600792
,3932964084.32985,60.9968566894531,-0.00544955069199204
,3932964084.32985,60.6741409301758,-0.00524088367819786
,3932964084.32985,60.3492889404297,-0.0050218622200191
,3932964084.32985,60.0238571166992,-0.00477887922897935
,3932964084.32985,59.6987152099609,-0.00452838651835918
,3932964084.32985,59.3735694885254,-0.00425476720556617
,3932964084.32985,59.0504302978516,-0.0039622955955565
,3932964084.32985,58.7279968261719,-0.00365635380148888
,3932964084.32985,58.4098587036133,-0.00332914106547833
,3932964084.32985,58.0929985046387,-0.00297764386050403
,3932964084.32985,57.7795715332031,-0.00260797585360706
,3932964084.32985,57.4678573608398,-0.00221140054054558
,3932964084.32985,57.1584281921387,-0.00179498561192304
,3932964084.32985,56.852855682373,-0.00135351938661188
,3932964084.32985,56.5491409301758,-0.000884839566424489
,3932964084.32985,56.2479972839355,-0.000384705432225019
,3932964084.32985,55.9491424560547,0.000136392467538826
,3932964084.32985,55.6539993286133,0.000693185022100806
,3932964084.32985,55.3607139587402,0.00128037598915398
,3932964084.32985,55.0684280395508,0.00190654839389026
,3932964084.32985,54.777286529541,0.00256761512719095
,3932964084.32985,54.4888572692871,0.00326575571671128
,3932964084.32985,54.2002868652344,0.0040074591524899
,3932964084.32985,53.9145698547363,0.00479258829727769
,3932964084.32985,53.6291389465332,0.00562713854014874
,3932964084.32985,53.3442878723145,0.00650657946243882
,3932964084.32985,53.0604286193848,0.00744070392102003
,3932964084.32985,52.7760009765625,0.00842571351677179
,3932964084.32985,52.4918556213379,0.0094728646799922
,3932964084.32985,52.2082862854004,0.0105807445943356
,3932964084.32985,51.9254302978516,0.0117459986358881
,3932964084.32985,51.6429977416992,0.0129684386774898
,3932964084.32985,51.3601417541504,0.0142688089981675
,3932964084.32985,51.0770034790039,0.0156308598816395
,3932964084.32985,50.7937164306641,0.0170676559209824
,3932964084.32985,50.5111427307129,0.0185684654861689
,3932964084.32985,50.2284278869629,0.0201327130198479
,3932964084.32985,49.9457130432129,0.0217642970383167
,3932964084.32985,49.6634292602539,0.0234560128301382
,3932964084.32985,49.3800010681152,0.0252097174525261
,3932964084.32985,49.0970001220703,0.0270108357071877
,3932964084.32985,48.8131446838379,0.0288586486130953
,3932964084.32985,48.5291404724121,0.0307320058345795
,3932964084.32985,48.245288848877,0.0326206386089325
,3932964084.32985,47.9611434936523,0.0345099344849586
,3932964084.32985,47.6777153015137,0.0363709628582001
,3932964084.32985,47.3931427001953,0.038176640868187
,3932964084.32985,47.1088562011719,0.0399113073945045
,3932964084.32985,46.8250007629395,0.0415214486420155
,3932964084.32985,46.5404281616211,0.0429926812648773
,3932964084.32985,46.2565727233887,0.0442617125809193
,3932964084.32985,45.9715728759766,0.0453045405447483
,3932964084.32985,45.6877136230469,0.0460514537990093
,3932964084.32985,45.4037170410156,0.0464739836752415
,3932964084.32985,45.1189994812012,0.0465019643306732
,3932964084.32985,44.8339996337891,0.0461056418716908
,3932964084.32985,44.5499992370605,0.0452195443212986
,3932964084.32985,44.2658576965332,0.0438107959926128
,3932964084.32985,43.9818572998047,0.0418431460857391
,3932964084.32985,43.6971435546875,0.0392727553844452
,3932964084.32985,43.4127159118652,0.0360790677368641
,3932964084.32985,43.1282844543457,0.0322565026581287
,3932964084.32985,42.8442878723145,0.02779645845294
,3932964084.32985,42.560001373291,0.0226870626211166
,3932964084.32985,42.2760009765625,0.016954967752099
,3932964084.32985,41.9914321899414,0.0106165930628777
,3932964084.32985,41.7077140808105,0.00371701410040259
,3932964084.32985,41.4234275817871,-0.00372801558114588
,3932964084.32985,41.1389999389648,-0.0116505967453122
,3932964084.32985,40.8551445007324,-0.0199908372014761
,3932964084.32985,40.5704307556152,-0.0287339892238379
,3932964084.32985,40.2871437072754,-0.0377401150763035
,3932964084.32985,40.003002166748,-0.0469908565282822
,3932964084.32985,39.7185707092285,-0.0564301945269108
,3932964084.32985,39.4355697631836,-0.065900981426239
,3932964084.32985,39.1508560180664,-0.0754261389374733
,3932964084.32985,38.8677139282227,-0.0848178565502167
,3932964084.32985,38.5831413269043,-0.094071589410305
,3932964084.32985,38.299144744873,-0.103020392358303
,3932964084.32985,38.0154304504395,-0.111621156334877
,3932964084.32985,37.7318572998047,-0.119726061820984
,3932964084.32985,37.4478569030762,-0.127268880605698
,3932964084.32985,37.1645698547363,-0.134128168225288
,3932964084.32985,36.8807144165039,-0.140259742736816
,3932964084.32985,36.5981407165527,-0.145527139306068
,3932964084.32985,36.3139991760254,-0.149885058403015
,3932964084.32985,36.0304298400879,-0.153254672884941
,3932964084.32985,35.7468566894531,-0.155589446425438
,3932964084.32985,35.4638557434082,-0.156847953796387
,3932964084.32985,35.1795692443848,-0.157001510262489
,3932964084.32985,34.8952865600586,-0.15606552362442
,3932964084.32985,34.6107139587402,-0.154048845171928
,3932964084.32985,34.3264274597168,-0.150967657566071
,3932964084.32985,34.043285369873,-0.146891549229622
,3932964084.32985,33.7584266662598,-0.141873672604561
,3932964084.32985,33.4739990234375,-0.135983571410179
,3932964084.32985,33.1902847290039,-0.129329919815063
,3932964084.32985,32.9062881469727,-0.12197307497263
,3932964084.32985,32.622142791748,-0.114035278558731
,3932964084.32985,32.3377151489258,-0.105578653514385
,3932964084.32985,32.0542831420898,-0.0967509374022484
,3932964084.32985,31.7700004577637,-0.0875882729887962
,3932964084.32985,31.4862861633301,-0.0782396048307419
,3932964084.32985,31.2021427154541,-0.0687546283006668
,3932964084.32985,30.9180011749268,-0.0592327862977982
,3932964084.32985,30.6331424713135,-0.0497575178742409
,3932964084.32985,30.3489990234375,-0.0404176898300648
,3932964084.32985,30.0655708312988,-0.0313035286962986
,3932964084.32985,29.7807159423828,-0.0224320739507675
,3932964084.32985,29.4965724945068,-0.0139156598597765
,3932964084.32985,29.2122859954834,-0.005803432315588
,3932964084.32985,28.9278564453125,0.00184258411172777
,3932964084.32985,28.6439990997314,0.00896680448204279
,3932964084.32985,28.3604297637939,0.0155281526967883
,3932964084.32985,28.0761432647705,0.0215207021683455
,3932964084.32985,27.792142868042,0.0268817152827978
,3932964084.32985,27.5077152252197,0.0316180028021336
,3932964084.32985,27.2238578796387,0.0357031859457493
,3932964084.32985,26.9395694732666,0.039154838770628
,3932964084.32985,26.655143737793,0.0419771037995815
,3932964084.32985,26.3719997406006,0.0441900864243507
,3932964084.32985,26.0869998931885,0.0458313263952732
,3932964084.32985,25.8030014038086,0.0469280518591404
,3932964084.32985,25.5187129974365,0.0475253574550152
,3932964084.32985,25.2348556518555,0.0476681180298328
,3932964084.32985,24.9505710601807,0.047405619174242
,3932964084.32985,24.6664276123047,0.0467836558818817
,3932964084.32985,24.3819999694824,0.0458553731441498
,3932964084.32985,24.0977153778076,0.0446627177298069
,3932964084.32985,23.8134269714355,0.0432651229202747
,3932964084.32985,23.5285720825195,0.0416898094117641
,3932964084.32985,23.2448558807373,0.0399887263774872
,3932964084.32985,22.9608573913574,0.0381875932216644
,3932964084.32985,22.6765727996826,0.0363262072205543
,3932964084.32985,22.3925704956055,0.0344180762767792
,3932964084.32985,22.1084270477295,0.0325041860342026
,3932964084.32985,21.8235721588135,0.0305845085531473
,3932964084.32985,21.5397148132324,0.0286959614604712
,3932964084.32985,21.2558574676514,0.02683868072927
,3932964084.32985,20.9710006713867,0.0250260159373283
,3932964084.32985,20.6864280700684,0.0232647154480219
,3932964084.32985,20.4024276733398,0.0215676017105579
,3932964084.32985,20.1182861328125,0.019933020696044
,3932964084.32985,19.8337154388428,0.0183621663600206
,3932964084.32985,19.5491428375244,0.0168615262955427
,3932964084.32985,19.2651424407959,0.0154357654973865
,3932964084.32985,18.9805717468262,0.0140782613307238
,3932964084.32985,18.6965713500977,0.0127855204045773
,3932964084.32985,18.4124279022217,0.0115696713328362
,3932964084.32985,18.1284294128418,0.0104087255895138
,3932964084.32985,17.8442859649658,0.00931613892316818
,3932964084.32985,17.5604286193848,0.00827929005026817
,3932964084.32985,17.2764282226562,0.00730875646695495
,3932964084.32985,16.9922847747803,0.00638750661164522
,3932964084.32985,16.7082862854004,0.00551683595404029
,3932964084.32985,16.4238567352295,0.0046980045735836
,3932964084.32985,16.1397151947021,0.00393036473542452
,3932964084.32985,15.8549995422363,0.00320635549724102
,3932964084.32985,15.5704288482666,0.00252558523789048
,3932964084.32985,15.2858572006226,0.0018819912802428
,3932964084.32985,15.0011425018311,0.00128795427735895
,3932964084.32985,14.71728515625,0.000720466952770948
,3932964084.32985,14.4331436157227,0.000190854087122716
,3932964084.32985,14.1481437683105,-0.000310369912767783
,3932964084.32985,13.8647146224976,-0.000781212584115565
,3932964084.32985,13.580714225769,-0.00121864257380366
,3932964084.32985,13.2967138290405,-0.00163991120643914
,3932964084.32985,13.0125722885132,-0.00203253561630845
,3932964084.32985,12.7282857894897,-0.00239915517158806
,3932964084.32985,12.4445714950562,-0.00274312519468367
,3932964084.32985,12.160285949707,-0.00307117216289043
,3932964084.32985,11.8759994506836,-0.00337180122733116
,3932964084.32985,11.5912857055664,-0.00366287608630955
,3932964084.32985,11.3074283599854,-0.00392723130062222
,3932964084.32985,11.0230007171631,-0.00418632430955768
,3932964084.32985,10.739143371582,-0.00441793072968721
,3932964084.32985,10.4541435241699,-0.0046483795158565
,3932964084.32985,10.1698570251465,-0.00486159371212125
,3932964084.32985,9.88628578186035,-0.00506295496597886
,3932964084.32985,9.60114288330078,-0.00525101646780968
,3932964084.32985,9.31771469116211,-0.00543001759797335
,3932964084.32985,9.03314304351807,-0.00559725100174546
,3932964084.32985,8.74842834472656,-0.00575416488572955
,3932964084.32985,8.46371364593506,-0.00590499863028526
,3932964084.32985,8.18000030517578,-0.00604583555832505
,3932964084.32985,7.89528560638428,-0.00618066126480699
,3932964084.32985,7.61142873764038,-0.00630295323207974