File: Curie-Weiss Analysis/Squid data/EuMnSb2/EuMnSb2_Ha_MvsH_2K.dat.scans.rw.dat
[Header]
; DC Raw Data File (default extension .raw)
; Copyright 2012, Quantum Design, Inc. All rights reserved.
TITLE,EuMnSb2
FILEOPENTIME,3933001230.47258,08/16/2024,8:20 pm
BYAPP,MPMS3 DC RAW DATA,1.0,1.1
INFO,MPMS3 Option Release 1.1.16 Build 433, Release 2.3.4.26,APPNAME
INFO,TCI274,COIL_SERIAL_NUMBER
INFO,0,MOMENT_UNITS
INFO,EuMnSb2,SAMPLE_MATERIAL
INFO,H//a,SAMPLE_COMMENT
INFO,2.7,SAMPLE_MASS
INFO,,SAMPLE_VOLUME
INFO,,SAMPLE_MOLECULAR_WEIGHT
INFO,,SAMPLE_SIZE
INFO,,SAMPLE_SHAPE
INFO,Quartz,SAMPLE_HOLDER
INFO,Standard,SAMPLE_HOLDER_DETAIL
INFO,66.26,SAMPLE_OFFSET
DATATYPE,COMMENT,1
DATATYPE,TIME,2
STARTUPAXIS,X,3
STARTUPAXIS,Y1,4
STARTUPAXIS,Y2,5
STARTUPAXIS,Y2,6
STARTUPAXIS,Y2,7
STARTUPAXIS,Y3,8
STARTUPAXIS,Y3,9
[Data]
Comment,Time Stamp (sec),Raw Position (mm),Raw Voltage (V),Processed Voltage (V),Fixed C Fitted (V),Free C Fitted (V)
,3933001220.91009,6.77342844009399,0.200185090303421
,3933001220.91009,6.87842845916748,0.20067922770977
,3933001220.91009,7.02771425247192,0.20110347867012
,3933001220.91009,7.21671438217163,0.201759696006775
,3933001220.91009,7.44099998474121,0.202231988310814
,3933001220.91009,7.6955714225769,0.203295692801476
,3933001220.91009,7.97614240646362,0.204304456710815
,3933001220.91009,8.27828598022461,0.204944372177124
,3933001220.91009,8.59814262390137,0.205110535025597
,3933001220.91009,8.92971420288086,0.205740079283714
,3933001220.91009,9.2708568572998,0.205356702208519
,3933001220.91009,9.61999988555908,0.205840393900871
,3933001220.91009,9.97200012207031,0.205378443002701
,3933001220.91009,10.3258571624756,0.205151826143265
,3933001220.91009,10.6798572540283,0.204236134886742
,3933001220.91009,11.0342855453491,0.203794598579407
,3933001220.91009,11.3871421813965,0.203018337488174
,3933001220.91009,11.7357139587402,0.202446654438972
,3933001220.91009,12.0817136764526,0.201682895421982
,3933001220.91009,12.4225721359253,0.201350063085556
,3933001220.91009,12.7581434249878,0.201118916273117
,3933001220.91009,13.0880002975464,0.200642570853233
,3933001220.91009,13.4134292602539,0.20043371617794
,3933001220.91009,13.7330007553101,0.200717464089394
,3933001220.91009,14.0477151870728,0.201099619269371
,3933001220.91009,14.3572854995728,0.201279789209366
,3933001220.91009,14.663857460022,0.202448114752769
,3933001220.91009,14.9662857055664,0.203268095850945
,3933001220.91009,15.2661428451538,0.204751089215279
,3933001220.91009,15.5618562698364,0.205608025193214
,3933001220.91009,15.8545713424683,0.207190155982971
,3933001220.91009,16.1442852020264,0.208918780088425
,3933001220.91009,16.4309997558594,0.211322635412216
,3933001220.91009,16.7157135009766,0.21359421312809
,3933001220.91009,16.9987144470215,0.216957211494446
,3933001220.91009,17.281286239624,0.220084398984909
,3933001220.91009,17.5634288787842,0.224423706531525
,3933001220.91009,17.8454284667969,0.2283556163311
,3933001220.91009,18.1255722045898,0.233430206775665
,3933001220.91009,18.4067134857178,0.238110974431038
,3933001220.91009,18.6872844696045,0.24332894384861
,3933001220.91009,18.96728515625,0.24857722222805
,3933001220.91009,19.2465705871582,0.253703206777573
,3933001220.91009,19.5267143249512,0.259500980377197
,3933001220.91009,19.8058567047119,0.265734940767288
,3933001220.91009,20.0858573913574,0.272814214229584
,3933001220.91009,20.3675727844238,0.279918938875198
,3933001220.91009,20.6481418609619,0.288336992263794
,3933001220.91009,20.9300003051758,0.295921504497528
,3933001220.91009,21.2124290466309,0.304543942213058
,3933001220.91009,21.4934272766113,0.312033653259277
,3933001220.91009,21.7755718231201,0.320229768753052
,3933001220.91009,22.0582866668701,0.327678859233856
,3933001220.91009,22.3410015106201,0.335273087024689
,3933001220.91009,22.6228561401367,0.342007875442505
,3933001220.91009,22.9055709838867,0.349310576915741
,3933001220.91009,23.1895694732666,0.355876892805099
,3933001220.91009,23.4744281768799,0.36251825094223
,3933001220.91009,23.7591438293457,0.367504835128784
,3933001220.91009,24.0439987182617,0.372023522853851
,3933001220.91009,24.3294296264648,0.374644637107849
,3933001220.91009,24.6132869720459,0.376263052225113
,3933001220.91009,24.8984279632568,0.375993818044662
,3933001220.91009,25.1827144622803,0.374255180358887
,3933001220.91009,25.46728515625,0.370645403861999
,3933001220.91009,25.7522850036621,0.365020960569382
,3933001220.91009,26.0371437072754,0.35762557387352
,3933001220.91009,26.3222846984863,0.347253143787384
,3933001220.91009,26.6068572998047,0.334502756595612
,3933001220.91009,26.8918571472168,0.318904608488083
,3933001220.91009,27.1770000457764,0.30168205499649
,3933001220.91009,27.4617137908936,0.28142324090004
,3933001220.91009,27.7468585968018,0.259833186864853
,3933001220.91009,28.0322856903076,0.235073015093803
,3933001220.91009,28.3162860870361,0.208916932344437
,3933001220.91009,28.6014289855957,0.179965332150459
,3933001220.91009,28.8862857818604,0.149812564253807
,3933001220.91009,29.1710014343262,0.117934882640839
,3933001220.91009,29.4557151794434,0.0847798138856888
,3933001220.91009,29.7397136688232,0.0503314100205898
,3933001220.91009,30.0248565673828,0.0153870936483145
,3933001220.91009,30.3101444244385,-0.0202692244201899
,3933001220.91009,30.5947151184082,-0.0557308606803417
,3933001220.91009,30.8798561096191,-0.0912514105439186
,3933001220.91009,31.1642837524414,-0.126020506024361
,3933001220.91009,31.4494285583496,-0.160015508532524
,3933001220.91009,31.7339992523193,-0.192693933844566
,3933001220.91009,32.0189971923828,-0.223881512880325
,3933001220.91009,32.3044281005859,-0.253284871578217
,3933001220.91009,32.5887145996094,-0.279783993959427
,3933001220.91009,32.8734283447266,-0.304669767618179
,3933001220.91009,33.1584281921387,-0.325752764940262
,3933001220.91009,33.4441413879395,-0.344069123268127
,3933001220.91009,33.7292861938477,-0.358056515455246
,3933001220.91009,34.0135726928711,-0.368940860033035
,3933001220.91009,34.2978553771973,-0.375104367733002
,3933001220.91009,34.5834274291992,-0.378058880567551
,3933001220.91009,34.8677139282227,-0.376528829336166
,3933001220.91009,35.1524276733398,-0.371274024248123
,3933001220.91009,35.4372863769531,-0.361633956432343
,3933001220.91009,35.7218589782715,-0.348823070526123
,3933001220.91009,36.0069999694824,-0.332394301891327
,3933001220.91009,36.2914276123047,-0.312422901391983
,3933001220.91009,36.576286315918,-0.288834422826767
,3933001220.91009,36.8612861633301,-0.263094812631607
,3933001220.91009,37.1469993591309,-0.234760582447052
,3933001220.91009,37.4322853088379,-0.204291939735413
,3933001220.91009,37.7182846069336,-0.172460198402405
,3933001220.91009,38.0027160644531,-0.139042869210243
,3933001220.91009,38.288143157959,-0.104820586740971
,3933001220.91009,38.5737152099609,-0.0699343085289001
,3933001220.91009,38.858715057373,-0.0350068658590317
,3933001220.91009,39.1439971923828,0.000265990005573258
,3933001220.91009,39.4292831420898,0.0344797559082508
,3933001220.91009,39.7138557434082,0.068289265036583
,3933001220.91009,39.9984283447266,0.100406348705292
,3933001220.91009,40.2831420898438,0.131906270980835
,3933001220.91009,40.567569732666,0.161126807332039
,3933001220.91009,40.8525695800781,0.18968366086483
,3933001220.91009,41.1372833251953,0.215057149529457
,3933001220.91009,41.4221420288086,0.23914310336113
,3933001220.91009,41.7072868347168,0.260831654071808
,3933001220.91009,41.9918556213379,0.280122339725494
,3933001220.91009,42.2775726318359,0.29682582616806
,3933001220.91009,42.5621452331543,0.311304092407227
,3933001220.91009,42.8461418151855,0.323292016983032
,3933001220.91009,43.1307144165039,0.332911759614944
,3933001220.91009,43.4155731201172,0.34035113453865
,3933001220.91009,43.701000213623,0.345877647399902
,3933001220.91009,43.9850006103516,0.349189192056656
,3933001220.91009,44.2698593139648,0.3507941365242
,3933001220.91009,44.554141998291,0.350502818822861
,3933001220.91009,44.8395690917969,0.348710924386978
,3933001220.91009,45.1248588562012,0.34586575627327
,3933001220.91009,45.4092864990234,0.341655880212784
,3933001220.91009,45.6952896118164,0.337123215198517
,3933001220.91009,45.9795684814453,0.331413686275482
,3933001220.91009,46.2639999389648,0.325812101364136
,3933001220.91009,46.5494270324707,0.318849474191666
,3933001220.91009,46.8341407775879,0.31226721405983
,3933001220.91009,47.1189994812012,0.305066019296646
,3933001220.91009,47.4032859802246,0.298841923475265
,3933001220.91009,47.6885681152344,0.291824400424957
,3933001220.91009,47.9732856750488,0.28594508767128
,3933001220.91009,48.257999420166,0.279630243778229
,3933001220.91009,48.5429992675781,0.274042844772339
,3933001220.91009,48.8278579711914,0.268047541379929
,3933001220.91009,49.1128578186035,0.263210088014603
,3933001220.91009,49.3972854614258,0.258023113012314
,3933001220.91009,49.6822853088379,0.253798007965088
,3933001220.91009,49.9678573608398,0.249556377530098
,3933001220.91009,50.2520027160645,0.245482057332993
,3933001220.91009,50.537425994873,0.242459788918495
,3933001220.91009,50.8221435546875,0.238877192139626
,3933001220.91009,51.1067123413086,0.236202478408813
,3933001220.91009,51.3908576965332,0.233322605490685
,3933001220.91009,51.6757125854492,0.231198042631149
,3933001220.91009,51.9599990844727,0.22857041656971
,3933001220.91009,52.244571685791,0.226927205920219
,3933001220.91009,52.5289993286133,0.224753752350807
,3933001220.91009,52.8132858276367,0.222939893603325
,3933001220.91009,53.097713470459,0.220715776085854
,3933001220.91009,53.3818550109863,0.219105646014214
,3933001220.91009,53.666431427002,0.216884180903435
,3933001220.91009,53.9511413574219,0.215072557330132
,3933001220.91009,54.2352867126465,0.213012292981148
,3933001220.91009,54.5200004577637,0.211175233125687
,3933001220.91009,54.8029975891113,0.208831638097763
,3933001220.91009,55.0879974365234,0.206616252660751
,3933001220.91009,55.3722839355469,0.204185962677002
,3933001220.91009,55.6570014953613,0.202111229300499
,3933001220.91009,55.9407119750977,0.199859723448753
,3933001220.91009,56.2239990234375,0.197027817368507
,3933001220.91009,56.5074272155762,0.194608062505722
,3933001220.91009,56.790714263916,0.191955432295799
,3933001220.91009,57.0739974975586,0.189307227730751
,3933001220.91009,57.3565711975098,0.18663589656353
,3933001220.91009,57.6401405334473,0.184362173080444
,3933001220.91009,57.9237174987793,0.181674212217331
,3933001220.91009,58.2084274291992,0.179136127233505
,3933001220.91009,58.4915733337402,0.176432371139526
,3933001220.91009,58.7744293212891,0.174267590045929
,3933001220.91009,59.0561408996582,0.171604350209236
,3933001220.91009,59.3392868041992,0.169500783085823
,3933001220.91009,59.6222839355469,0.167198866605759
,3933001220.91009,59.9058609008789,0.165420144796371
,3933001220.91009,60.1879997253418,0.163453057408333
,3933001220.91009,60.470287322998,0.161604434251785
,3933001220.91009,60.7522850036621,0.160173609852791
,3933001220.91009,61.0347137451172,0.158902630209923
,3933001220.91009,61.3154296875,0.157534882426262
,3933001220.91009,61.5968551635742,0.156684324145317
,3933001220.91009,61.8771438598633,0.156233876943588
,3933001220.91009,62.1562843322754,0.155569016933441
,3933001220.91009,62.4358596801758,0.155327528715134
,3933001220.91009,62.7134284973145,0.15547887980938
,3933001220.91009,62.9904289245606,0.155874282121658
,3933001220.91009,63.2655715942383,0.156035825610161
,3933001220.91009,63.5394287109375,0.156867906451225
,3933001220.91009,63.8121452331543,0.157563641667366
,3933001225.6284,64.3964309692383,0.156740218400955
,3933001225.6284,64.2289962768555,0.155725836753845
,3933001225.6284,64.0350036621094,0.15486566722393
,3933001225.6284,63.8212852478027,0.153897225856781
,3933001225.6284,63.5892868041992,0.153124496340752
,3933001225.6284,63.3398590087891,0.152298226952553
,3933001225.6284,63.0767135620117,0.151797458529472
,3933001225.6284,62.8007125854492,0.151061683893204
,3933001225.6284,62.513858795166,0.150684908032417
,3933001225.6284,62.2171440124512,0.150541305541992
,3933001225.6284,61.9129981994629,0.150513052940369
,3933001225.6284,61.6029968261719,0.150990426540375
,3933001225.6284,61.2872848510742,0.152087464928627
,3933001225.6284,60.9684295654297,0.15315580368042
,3933001225.6284,60.6465721130371,0.154403030872345
,3933001225.6284,60.3232879638672,0.156028479337692
,3933001225.6284,59.9979972839356,0.157716691493988
,3933001225.6284,59.6748580932617,0.159654855728149
,3933001225.6284,59.3511428833008,0.161949440836906
,3933001225.6284,59.0294303894043,0.164173975586891
,3933001225.6284,58.7091407775879,0.166464403271675
,3933001225.6284,58.3911437988281,0.1692795753479
,3933001225.6284,58.0751419067383,0.171716511249542
,3933001225.6284,57.7628555297852,0.174708321690559
,3933001225.6284,57.4514312744141,0.177112579345703
,3933001225.6284,57.1434288024902,0.179959371685982
,3933001225.6284,56.8371429443359,0.182622268795967
,3933001225.6284,56.5341415405273,0.185205295681953
,3933001225.6284,56.2334289550781,0.18782040476799
,3933001225.6284,55.9352874755859,0.190612703561783
,3933001225.6284,55.6391410827637,0.192780882120132
,3933001225.6284,55.3447113037109,0.195254653692245
,3933001225.6284,55.0522842407227,0.19741478562355
,3933001225.6284,54.7615737915039,0.199612602591515
,3933001225.6284,54.4718551635742,0.201631903648376
,3933001225.6284,54.1831436157227,0.203570351004601
,3933001225.6284,53.8965721130371,0.205197602510452
,3933001225.6284,53.6091423034668,0.206953749060631
,3933001225.6284,53.3237152099609,0.208675235509872
,3933001225.6284,53.0389976501465,0.210820004343986
,3933001225.6284,52.7541389465332,0.212304592132568
,3933001225.6284,52.470287322998,0.214120179414749
,3933001225.6284,52.1872863769531,0.216143026947975
,3933001225.6284,51.9029998779297,0.217897817492485
,3933001225.6284,51.6204299926758,0.220272675156593
,3933001225.6284,51.3377151489258,0.222743108868599
,3933001225.6284,51.0529975891113,0.225483134388924
,3933001225.6284,50.7702865600586,0.228169947862625
,3933001225.6284,50.486141204834,0.231095999479294
,3933001225.6284,50.2031440734863,0.234800338745117
,3933001225.6284,49.9204292297363,0.238104432821274
,3933001225.6284,49.6372833251953,0.242410004138947
,3933001225.6284,49.3531455993652,0.246687486767769
,3933001225.6284,49.0698585510254,0.25135537981987
,3933001225.6284,48.7854309082031,0.256650239229202
,3933001225.6284,48.5009994506836,0.261811524629593
,3933001225.6284,48.216854095459,0.267540037631989
,3933001225.6284,47.9331436157227,0.273164421319962
,3933001225.6284,47.6485710144043,0.279226362705231
,3933001225.6284,47.3634262084961,0.285399615764618
,3933001225.6284,47.0787162780762,0.291999816894531
,3933001225.6284,46.7941398620605,0.298364669084549
,3933001225.6284,46.5092887878418,0.304678201675415
,3933001225.6284,46.2239990234375,0.311266273260117
,3933001225.6284,45.9401397705078,0.31694620847702
,3933001225.6284,45.654712677002,0.322435617446899
,3933001225.6284,45.3698577880859,0.326596111059189
,3933001225.6284,45.0849990844727,0.330292135477066
,3933001225.6284,44.7999992370605,0.332920461893082
,3933001225.6284,44.5152893066406,0.334105879068375
,3933001225.6284,44.231143951416,0.333565413951874
,3933001225.6284,43.9462852478027,0.331731647253036
,3933001225.6284,43.6617126464844,0.327658504247665
,3933001225.6284,43.3770027160645,0.32213094830513
,3933001225.6284,43.0920028686523,0.314153373241425
,3933001225.6284,42.8064308166504,0.304206192493439
,3933001225.6284,42.5214309692383,0.291444301605225
,3933001225.6284,42.2367134094238,0.276622295379639
,3933001225.6284,41.9514312744141,0.259182184934616
,3933001225.6284,41.6674270629883,0.239638730883598
,3933001225.6284,41.3825721740723,0.217383861541748
,3933001225.6284,41.097713470459,0.193013891577721
,3933001225.6284,40.812572479248,0.167121082544327
,3933001225.6284,40.5282859802246,0.138700380921364
,3933001225.6284,40.2441444396973,0.108707882463932
,3933001225.6284,39.9594268798828,0.0769382938742638
,3933001225.6284,39.6747131347656,0.0440551415085793
,3933001225.6284,39.3898544311523,0.0101861106231809
,3933001225.6284,39.1055717468262,-0.0246484130620956
,3933001225.6284,38.8209991455078,-0.0600035265088081
,3933001225.6284,38.5367126464844,-0.0948500335216522
,3933001225.6284,38.2518577575684,-0.130082920193672
,3933001225.6284,37.9678573608398,-0.164056077599525
,3933001225.6284,37.6834259033203,-0.19765031337738
,3933001225.6284,37.3981437683105,-0.22936025261879
,3933001225.6284,37.114143371582,-0.260105550289154
,3933001225.6284,36.8298568725586,-0.288259238004684
,3933001225.6284,36.5464286804199,-0.313959687948227
,3933001225.6284,36.2631416320801,-0.336949914693832
,3933001225.6284,35.9801445007324,-0.356529206037521
,3933001225.6284,35.6971435546875,-0.37306934595108
,3933001225.6284,35.4114265441895,-0.386341482400894
,3933001225.6284,35.1272850036621,-0.395516216754913
,3933001225.6284,34.8432846069336,-0.400605171918869
,3933001225.6284,34.5581436157227,-0.402106553316116
,3933001225.6284,34.2729988098145,-0.399369210004807
,3933001225.6284,33.9885711669922,-0.392764896154404
,3933001225.6284,33.7039985656738,-0.381769418716431
,3933001225.6284,33.4192848205566,-0.367591112852097
,3933001225.6284,33.1352844238281,-0.349626690149307
,3933001225.6284,32.8498573303223,-0.32858669757843
,3933001225.6284,32.5651435852051,-0.304042667150497
,3933001225.6284,32.280143737793,-0.2773816883564
,3933001225.6284,31.9952850341797,-0.248026609420776
,3933001225.6284,31.7104301452637,-0.217322751879692
,3933001225.6284,31.4267139434814,-0.18460588157177
,3933001225.6284,31.1411418914795,-0.151106759905815
,3933001225.6284,30.8574295043945,-0.116669125854969
,3933001225.6284,30.5718574523926,-0.081832267343998
,3933001225.6284,30.2875709533691,-0.0467720068991184
,3933001225.6284,30.0034275054932,-0.0115675590932369
,3933001225.6284,29.7188568115234,0.0231208987534046
,3933001225.6284,29.4337139129639,0.0570094138383865
,3933001225.6284,29.149284362793,0.0900430977344513
,3933001225.6284,28.864429473877,0.121689058840275
,3933001225.6284,28.5808563232422,0.151580736041069
,3933001225.6284,28.2952861785889,0.179764747619629
,3933001225.6284,28.0104293823242,0.205962359905243
,3933001225.6284,27.725715637207,0.230272531509399
,3933001225.6284,27.4411430358887,0.252290815114975
,3933001225.6284,27.1564273834229,0.271958619356155
,3933001225.6284,26.8714275360107,0.289019614458084
,3933001225.6284,26.5867137908936,0.304115861654282
,3933001225.6284,26.3025703430176,0.316078871488571
,3933001225.6284,26.0179996490479,0.326426804065704
,3933001225.6284,25.7334270477295,0.334064811468124
,3933001225.6284,25.4487133026123,0.339747965335846
,3933001225.6284,25.1642837524414,0.343139082193375
,3933001225.6284,24.8802852630615,0.344625443220139
,3933001225.6284,24.5951442718506,0.344238817691803
,3933001225.6284,24.3099994659424,0.342662513256073
,3933001225.6284,24.0254287719727,0.339198768138886
,3933001225.6284,23.740571975708,0.334320932626724
,3933001225.6284,23.4555721282959,0.328737437725067
,3933001225.6284,23.1704292297363,0.322294622659683
,3933001225.6284,22.885856628418,0.315719366073608
,3933001225.6284,22.601713180542,0.308195233345032
,3933001225.6284,22.316858291626,0.300223916769028
,3933001225.6284,22.0321426391602,0.292223572731018
,3933001225.6284,21.7468585968018,0.28402841091156
,3933001225.6284,21.4635715484619,0.275622546672821
,3933001225.6284,21.1778564453125,0.267158031463623
,3933001225.6284,20.8929996490479,0.258910089731216
,3933001225.6284,20.6082859039307,0.25101912021637
,3933001225.6284,20.3229999542236,0.243098020553589
,3933001225.6284,20.0380001068115,0.235486164689064
,3933001225.6284,19.7531433105469,0.228227332234383
,3933001225.6284,19.4688568115234,0.221491456031799
,3933001225.6284,19.1842861175537,0.214868575334549
,3933001225.6284,18.8998565673828,0.208942294120789
,3933001225.6284,18.6142864227295,0.203598782420158
,3933001225.6284,18.3301429748535,0.198407366871834
,3933001225.6284,18.0450000762939,0.193316638469696
,3933001225.6284,17.760570526123,0.188526377081871
,3933001225.6284,17.4758567810059,0.184623226523399
,3933001225.6284,17.1908569335938,0.180592373013496
,3933001225.6284,16.9058570861816,0.177147507667542
,3933001225.6284,16.6212844848633,0.173482343554497
,3933001225.6284,16.3365707397461,0.170799732208252
,3933001225.6284,16.0524272918701,0.168391153216362
,3933001225.6284,15.7675724029541,0.166005909442902
,3933001225.6284,15.4828577041626,0.164281770586967
,3933001225.6284,15.1975717544556,0.162593051791191
,3933001225.6284,14.9130001068115,0.161499574780464
,3933001225.6284,14.6285715103149,0.160330668091774
,3933001225.6284,14.3435716629028,0.159478664398193
,3933001225.6284,14.0591430664062,0.158821001648903
,3933001225.6284,13.7735719680786,0.158155098557472
,3933001225.6284,13.4892854690552,0.157999590039253
,3933001225.6284,13.204571723938,0.157124131917954
,3933001225.6284,12.919713973999,0.157186448574066
,3933001225.6284,12.6354284286499,0.157352164387703
,3933001225.6284,12.3505716323853,0.157404199242592
,3933001225.6284,12.0654287338257,0.157676428556442
,3933001225.6284,11.7811422348022,0.158106073737144
,3933001225.6284,11.4957141876221,0.158530801534653
,3933001225.6284,11.2109994888306,0.158829629421234
,3933001225.6284,10.9269990921021,0.159499764442444
,3933001225.6284,10.6415710449219,0.159263208508492
,3933001225.6284,10.3574275970459,0.159754395484924
,3933001225.6284,10.0721426010132,0.159621253609657
,3933001225.6284,9.787428855896,0.159706354141235
,3933001225.6284,9.50257110595703,0.159290581941605
,3933001225.6284,9.21771430969238,0.159309461712837
,3933001225.6284,8.93285751342773,0.158510953187942
,3933001225.6284,8.64828586578369,0.158716753125191
,3933001225.6284,8.36357116699219,0.157801002264023
,3933001225.6284,8.07828521728516,0.157602056860924
,3933001225.6284,7.79414319992065,0.156547605991364
,3933001225.6284,7.50928592681885,0.155696392059326